<?xml version="1.0" encoding="utf-8"?>
<!-- This URDF was automatically created by SolidWorks to URDF Exporter! Originally created by Stephen Brawner (brawner@gmail.com) 
     Commit Version: 1.5.1-0-g916b5db  Build Version: 1.5.7152.31018
     For more information, please see http://wiki.ros.org/sw_urdf_exporter -->
<robot
  name="banana_robot">
  <link
    name="base_link">
    <inertial>
      <origin
        xyz="-0.373170543665901 0.0159197538702998 -0.0131271809566358"
        rpy="0 0 0" />
      <mass
        value="1191.08155050657" />
      <inertia
        ixx="372.944863207244"
        ixy="4.30107780092459"
        ixz="47.9423790748847"
        iyy="642.319209146518"
        iyz="-11.7750865092983"
        izz="892.824842551087" />
    </inertial>
    <visual>
      <origin
        xyz="0 0 0"
        rpy="0 0 0" />
      <geometry>
        <mesh
          filename="package://urdf_sim_tutorial/meshes/base_link.STL" />
      </geometry>
      <material
        name="">
        <color
          rgba="0.792156862745098 0.819607843137255 0.933333333333333 1" />
      </material>
    </visual>
    <collision>
      <origin
        xyz="0 0 0"
        rpy="0 0 0" />
      <geometry>
        <mesh
          filename="package://urdf_sim_tutorial/meshes/base_link.STL" />
      </geometry>
    </collision>
  </link>
  <link
    name="wheel1">
    <inertial>
      <origin
        xyz="0 0 -2.2204E-16"
        rpy="0 0 0" />
      <mass
        value="3.2398" />
      <inertia
        ixx="0.015739"
        ixy="2.1176E-20"
        ixz="-4.2352E-20"
        iyy="0.010876"
        iyz="-5.5739E-19"
        izz="0.010876" />
    </inertial>
    <visual>
      <origin
        xyz="0 0 0"
        rpy="0 0 0" />
      <geometry>
        <mesh
          filename="package://urdf_sim_tutorial/meshes/wheel1.STL" />
      </geometry>
      <material
        name="">
        <color
          rgba="0.79216 0.81961 0.93333 1" />
      </material>
    </visual>
    <collision>
      <origin
        xyz="0 0 0"
        rpy="0 0 0" />
      <geometry>
        <mesh
          filename="package://urdf_sim_tutorial/meshes/wheel1.STL" />
      </geometry>
    </collision>
  </link>
  <joint
    name="base_link_to_wheel1"
    type="continuous">
    <origin
      xyz="1.125 -0.725 -0.37"
      rpy="0 0 0" />
    <parent
      link="base_link" />
    <child
      link="wheel1" />
    <axis
      xyz="1 0 0" />
    <limit
      effort="1000"
      velocity="0.5" />
  </joint>
  <link
    name="wheel2">
    <inertial>
      <origin
        xyz="4.33680868994202E-18 4.44089209850063E-16 0"
        rpy="0 0 0" />
      <mass
        value="3.23976742401447" />
      <inertia
        ixx="0.0157386428837067"
        ixy="1.12937726300572E-20"
        ixz="-4.2351647362715E-20"
        iyy="0.0108759237861092"
        iyz="-2.1791246057097E-19"
        izz="0.0108759237861092" />
    </inertial>
    <visual>
      <origin
        xyz="0 0 0"
        rpy="0 0 0" />
      <geometry>
        <mesh
          filename="package://urdf_sim_tutorial/meshes/wheel2.STL" />
      </geometry>
      <material
        name="">
        <color
          rgba="0.792156862745098 0.819607843137255 0.933333333333333 1" />
      </material>
    </visual>
    <collision>
      <origin
        xyz="0 0 0"
        rpy="0 0 0" />
      <geometry>
        <mesh
          filename="package://urdf_sim_tutorial/meshes/wheel2.STL" />
      </geometry>
    </collision>
  </link>
  <joint
    name="base_link_to_wheel2"
    type="continuous">
    <origin
      xyz="-1.125 -0.725 -0.37"
      rpy="0 0 0" />
    <parent
      link="base_link" />
    <child
      link="wheel2" />
    <axis
      xyz="1 0 0" />
    <limit
      effort="1000"
      velocity="0.5" />
  </joint>
  <link
    name="wheel3">
    <inertial>
      <origin
        xyz="4.3368E-18 0 0"
        rpy="0 0 0" />
      <mass
        value="3.2398" />
      <inertia
        ixx="0.015739"
        ixy="1.1294E-20"
        ixz="-4.2352E-20"
        iyy="0.010876"
        iyz="-2.1791E-19"
        izz="0.010876" />
    </inertial>
    <visual>
      <origin
        xyz="0 0 0"
        rpy="0 0 0" />
      <geometry>
        <mesh
          filename="package://urdf_sim_tutorial/meshes/wheel3.STL" />
      </geometry>
      <material
        name="">
        <color
          rgba="0.79216 0.81961 0.93333 1" />
      </material>
    </visual>
    <collision>
      <origin
        xyz="0 0 0"
        rpy="0 0 0" />
      <geometry>
        <mesh
          filename="package://urdf_sim_tutorial/meshes/wheel3.STL" />
      </geometry>
    </collision>
  </link>
  <joint
    name="base_link_to_wheel3"
    type="continuous">
    <origin
      xyz="-1.125 0.725 -0.37"
      rpy="0 0 0" />
    <parent
      link="base_link" />
    <child
      link="wheel3" />
    <axis
      xyz="1 0 0" />
    <limit
      effort="1000"
      velocity="0.5" />
  </joint>
  <link
    name="wheel4">
    <inertial>
      <origin
        xyz="0 0 -2.22044604925031E-16"
        rpy="0 0 0" />
      <mass
        value="3.23976742401446" />
      <inertia
        ixx="0.0157386428837066"
        ixy="2.11758236813573E-20"
        ixz="-4.2351647362715E-20"
        iyy="0.0108759237861092"
        iyz="-5.57387383962731E-19"
        izz="0.0108759237861092" />
    </inertial>
    <visual>
      <origin
        xyz="0 0 0"
        rpy="0 0 0" />
      <geometry>
        <mesh
          filename="package://urdf_sim_tutorial/meshes/wheel4.STL" />
      </geometry>
      <material
        name="">
        <color
          rgba="0.792156862745098 0.819607843137255 0.933333333333333 1" />
      </material>
    </visual>
    <collision>
      <origin
        xyz="0 0 0"
        rpy="0 0 0" />
      <geometry>
        <mesh
          filename="package://urdf_sim_tutorial/meshes/wheel4.STL" />
      </geometry>
    </collision>
  </link>
  <joint
    name="base_link_to_wheel4"
    type="continuous">
    <origin
      xyz="1.125 0.725 -0.37"
      rpy="0 0 0" />
    <parent
      link="base_link" />
    <child
      link="wheel4" />
    <axis
      xyz="1 0 0" />
    <limit
      effort="1000"
      velocity="0.5" />
  </joint>
  <link
    name="arm1_link1">
    <inertial>
      <origin
        xyz="1.11022302462516E-16 0 -0.0899421612400215"
        rpy="0 0 0" />
      <mass
        value="30.3337963399309" />
      <inertia
        ixx="0.643246565913193"
        ixy="-5.82335151237331E-18"
        ixz="-1.26757702916476E-18"
        iyy="0.626370474669819"
        iyz="4.27252040466284E-17"
        izz="0.408564224727811" />
    </inertial>
    <visual>
      <origin
        xyz="0 0 0"
        rpy="0 0 0" />
      <geometry>
        <mesh
          filename="package://urdf_sim_tutorial/meshes/arm1_link1.STL" />
      </geometry>
      <material
        name="">
        <color
          rgba="0.792156862745098 0.819607843137255 0.933333333333333 1" />
      </material>
    </visual>
    <collision>
      <origin
        xyz="0 0 0"
        rpy="0 0 0" />
      <geometry>
        <mesh
          filename="package://urdf_sim_tutorial/meshes/arm1_link1.STL" />
      </geometry>
    </collision>
  </link>
  <joint
    name="base_link_to_arm1_link1"
    type="revolute">
    <origin
      xyz="-0.6 -0.3 0.25"
      rpy="0 0 0" />
    <parent
      link="base_link" />
    <child
      link="arm1_link1" />
    <axis
      xyz="0 0 1" />
    <limit
      lower="-3.1415"
      upper="3.1415"
      effort="1000"
      velocity="0.5" />
  </joint>
  <link
    name="arm1_link2">
    <inertial>
      <origin
        xyz="0.902983819640065 -4.44089209850063E-16 -2.22044604925031E-15"
        rpy="0 0 0" />
      <mass
        value="43.5099555921539" />
      <inertia
        ixx="0.168281643345465"
        ixy="-1.25394155064484E-15"
        ixz="2.36405582026492E-15"
        iyy="14.0055904746337"
        iyz="2.84649869472838E-18"
        izz="13.9984094945799" />
    </inertial>
    <visual>
      <origin
        xyz="0 0 0"
        rpy="0 0 0" />
      <geometry>
        <mesh
          filename="package://urdf_sim_tutorial/meshes/arm1_link2.STL" />
      </geometry>
      <material
        name="">
        <color
          rgba="0.792156862745098 0.819607843137255 0.933333333333333 1" />
      </material>
    </visual>
    <collision>
      <origin
        xyz="0 0 0"
        rpy="0 0 0" />
      <geometry>
        <mesh
          filename="package://urdf_sim_tutorial/meshes/arm1_link2.STL" />
      </geometry>
    </collision>
  </link>
  <joint
    name="arm1_link1_to_link2"
    type="revolute">
    <origin
      xyz="0 0 0.13"
      rpy="1.5708 0 0" />
    <parent
      link="arm1_link1" />
    <child
      link="arm1_link2" />
    <axis
      xyz="0 0 1" />
    <limit
      lower="-3.1415"
      upper="3.1415"
      effort="1000"
      velocity="0.5" />
  </joint>
  <link
    name="arm1_link3">
    <inertial>
      <origin
        xyz="0.71159 0 -2.2204E-15"
        rpy="0 0 0" />
      <mass
        value="23.263" />
      <inertia
        ixx="0.063255"
        ixy="5.7492E-16"
        ixz="1.4796E-15"
        iyy="4.7295"
        iyz="-2.565E-18"
        izz="4.7523" />
    </inertial>
    <visual>
      <origin
        xyz="0 0 0"
        rpy="0 0 0" />
      <geometry>
        <mesh
          filename="package://urdf_sim_tutorial/meshes/arm1_link3.STL" />
      </geometry>
      <material
        name="">
        <color
          rgba="0.79216 0.81961 0.93333 1" />
      </material>
    </visual>
    <collision>
      <origin
        xyz="0 0 0"
        rpy="0 0 0" />
      <geometry>
        <mesh
          filename="package://urdf_sim_tutorial/meshes/arm1_link3.STL" />
      </geometry>
    </collision>
  </link>
  <joint
    name="arm1_link2_to_link3"
    type="revolute">
    <origin
      xyz="2 0 0"
      rpy="0 0 0" />
    <parent
      link="arm1_link2" />
    <child
      link="arm1_link3" />
    <axis
      xyz="0 0 1" />
    <limit
      lower="-3.1415"
      upper="3.1415"
      effort="1000"
      velocity="0.5" />
  </joint>
  <link
    name="arm1_link4">
    <inertial>
      <origin
        xyz="0.089507 0 0.014927"
        rpy="0 0 0" />
      <mass
        value="1.0313" />
      <inertia
        ixx="0.0014597"
        ixy="7.6981E-20"
        ixz="-0.0017111"
        iyy="0.0087877"
        iyz="1.4478E-20"
        izz="0.0082624" />
    </inertial>
    <visual>
      <origin
        xyz="0 0 0"
        rpy="0 0 0" />
      <geometry>
        <mesh
          filename="package://urdf_sim_tutorial/meshes/arm1_link4_new.STL" />
      </geometry>
      <material
        name="">
        <color
          rgba="0.79216 0.81961 0.93333 1" />
      </material>
    </visual>
    <collision>
      <origin
        xyz="0 0 0"
        rpy="0 0 0" />
      <geometry>
        <mesh
          filename="package://urdf_sim_tutorial/meshes/arm1_link4_new.STL" />
      </geometry>
    </collision>
  </link>
  <joint
    name="arm1_link3_to_link4"
    type="revolute">
    <origin
      xyz="1.5 0 0"
      rpy="0 0 0" />
    <parent
      link="arm1_link3" />
    <child
      link="arm1_link4" />
    <axis
      xyz="0 0 1" />
    <limit
      lower="-3.1415"
      upper="3.1415"
      effort="1000"
      velocity="0.5" />
  </joint>
  <link
    name="left_gripper">
    <inertial>
      <origin
        xyz="0.09047 0.011404 4.4409E-16"
        rpy="0 0 0" />
      <mass
        value="0.44546" />
      <inertia
        ixx="0.00039647"
        ixy="0.00026652"
        ixz="-8.9444E-20"
        iyy="0.0018436"
        iyz="4.5128E-21"
        izz="0.0021012" />
    </inertial>
    <visual>
      <origin
        xyz="0 0 0"
        rpy="0 0 0" />
      <geometry>
        <mesh
          filename="package://urdf_sim_tutorial/meshes/left_gripper_new.STL" />
      </geometry>
      <material
        name="">
        <color
          rgba="0.79216 0.81961 0.93333 1" />
      </material>
    </visual>
    <collision>
      <origin
        xyz="0 0 0"
        rpy="0 0 0" />
      <geometry>
        <mesh
          filename="package://urdf_sim_tutorial/meshes/left_gripper_new.STL" />
      </geometry>
    </collision>
  </link>
  <joint
    name="arm1_link4_to_left_gripper"
    type="revolute">
    <origin
      xyz="0.13 0 -0.025"
      rpy="-1.5708 0 0" />
    <parent
      link="arm1_link4" />
    <child
      link="left_gripper" />
    <axis
      xyz="0 0 1" />
    <limit
      lower="-3.1415"
      upper="3.1415"
      effort="1000"
      velocity="0.2" />
  </joint>
  <link
    name="arm2_link1">
    <inertial>
      <origin
        xyz="1.11022302462516E-16 4.44089209850063E-16 0.447068258452662"
        rpy="0 0 0" />
      <mass
        value="51.8945243112741" />
      <inertia
        ixx="7.36751822699342"
        ixy="6.19180632691988E-18"
        ixz="-9.36404622380061E-17"
        iyy="7.36751822699342"
        iyz="9.3859731137619E-17"
        izz="0.374092038847274" />
    </inertial>
    <visual>
      <origin
        xyz="0 0 0"
        rpy="0 0 0" />
      <geometry>
        <mesh
          filename="package://urdf_sim_tutorial/meshes/arm2_link1.STL" />
      </geometry>
      <material
        name="">
        <color
          rgba="0.792156862745098 0.819607843137255 0.933333333333333 1" />
      </material>
    </visual>
    <collision>
      <origin
        xyz="0 0 0"
        rpy="0 0 0" />
      <geometry>
        <mesh
          filename="package://urdf_sim_tutorial/meshes/arm2_link1.STL" />
      </geometry>
    </collision>
  </link>
  <joint
    name="base_link_to_arm2_link1"
    type="prismatic">
    <origin
      xyz="-0.6 0.3 0.25"
      rpy="0 0 0" />
    <parent
      link="base_link" />
    <child
      link="arm2_link1" />
    <axis
      xyz="0 0 1" />
    <limit
      lower="0"
      upper="1.2"
      effort="1000"
      velocity="0.5" />
  </joint>
  <link
    name="arm2_link2">
    <inertial>
      <origin
        xyz="0.9137 0 0"
        rpy="0 0 0" />
      <mass
        value="42.999" />
      <inertia
        ixx="0.16533"
        ixy="1.2305E-16"
        ixz="-3.9882E-17"
        iyy="13.581"
        iyz="-2.5095E-19"
        izz="13.577" />
    </inertial>
    <visual>
      <origin
        xyz="0 0 0"
        rpy="0 0 0" />
      <geometry>
        <mesh
          filename="package://urdf_sim_tutorial/meshes/arm2_link2.STL" />
      </geometry>
      <material
        name="">
        <color
          rgba="0.79216 0.81961 0.93333 1" />
      </material>
    </visual>
    <collision>
      <origin
        xyz="0 0 0"
        rpy="0 0 0" />
      <geometry>
        <mesh
          filename="package://urdf_sim_tutorial/meshes/arm2_link2.STL" />
      </geometry>
    </collision>
  </link>
  <joint
    name="arm2_link1_to_link2"
    type="revolute">
    <origin
      xyz="0 0 1.115"
      rpy="0 0 0" />
    <parent
      link="arm2_link1" />
    <child
      link="arm2_link2" />
    <axis
      xyz="0 0 1" />
    <limit
      lower="-3.1415"
      upper="3.1415"
      effort="1000"
      velocity="0.5" />
  </joint>
  <link
    name="arm2_link3">
    <inertial>
      <origin
        xyz="0.68949 4.4409E-16 0"
        rpy="0 0 0" />
      <mass
        value="22.513" />
      <inertia
        ixx="0.061693"
        ixy="6.1041E-18"
        ixz="5.298E-18"
        iyy="4.3877"
        iyz="3.9174E-19"
        izz="4.4092" />
    </inertial>
    <visual>
      <origin
        xyz="0 0 0"
        rpy="0 0 0" />
      <geometry>
        <mesh
          filename="package://urdf_sim_tutorial/meshes/arm2_link3.STL" />
      </geometry>
      <material
        name="">
        <color
          rgba="0.79216 0.81961 0.93333 1" />
      </material>
    </visual>
    <collision>
      <origin
        xyz="0 0 0"
        rpy="0 0 0" />
      <geometry>
        <mesh
          filename="package://urdf_sim_tutorial/meshes/arm2_link3.STL" />
      </geometry>
    </collision>
  </link>
  <joint
    name="arm2_link2_to_link3"
    type="revolute">
    <origin
      xyz="2 0 0"
      rpy="0 0 0" />
    <parent
      link="arm2_link2" />
    <child
      link="arm2_link3" />
    <axis
      xyz="0 0 1" />
    <limit
      lower="-3.1415"
      upper="3.1415"
      effort="1000"
      velocity="0.5" />
  </joint>
  <link
    name="arm2_link4">
    <inertial>
      <origin
        xyz="0.10627 0.0054035 4.4409E-16"
        rpy="0 0 0" />
      <mass
        value="2.6025" />
      <inertia
        ixx="0.0050927"
        ixy="-0.0023728"
        ixz="4.1284E-20"
        iyy="0.027771"
        iyz="-1.1149E-19"
        izz="0.031534" />
    </inertial>
    <visual>
      <origin
        xyz="0 0 0"
        rpy="0 0 0" />
      <geometry>
        <mesh
          filename="package://urdf_sim_tutorial/meshes/arm2_link4.STL" />
      </geometry>
      <material
        name="">
        <color
          rgba="0.79216 0.81961 0.93333 1" />
      </material>
    </visual>
    <collision>
      <origin
        xyz="0 0 0"
        rpy="0 0 0" />
      <geometry>
        <mesh
          filename="package://urdf_sim_tutorial/meshes/arm2_link4.STL" />
      </geometry>
    </collision>
  </link>
  <joint
    name="arm2_link3_to_link4"
    type="revolute">
    <origin
      xyz="1.5 0 0"
      rpy="0 0 0" />
    <parent
      link="arm2_link3" />
    <child
      link="arm2_link4" />
    <axis
      xyz="0 0 1" />
    <limit
      lower="-3.1415"
      upper="3.1415"
      effort="1000"
      velocity="0.5" />
  </joint>

<link name="world" />
<joint name="world_joint"  type="fixed">
    <origin xyz="0 0 0" rpy="0 0 0" />
    <parent link="world"/>
    <child link="base_link"/>
</joint>


<transmission name="trans_base_link_to_wheel1">
        <type>transmission_interface/SimpleTransmission</type>
        <joint name="base_link_to_wheel1">
            <hardwareInterface>PositionJointInterface</hardwareInterface>
        </joint>
        <actuator name="base_link_to_wheel1_motor">
            <hardwareInterface>PositionJointInterface</hardwareInterface>
            <mechanicalReduction>1</mechanicalReduction>
        </actuator>
    </transmission>
    <transmission name="trans_base_link_to_wheel2">
        <type>transmission_interface/SimpleTransmission</type>
        <joint name="base_link_to_wheel2">
            <hardwareInterface>PositionJointInterface</hardwareInterface>
        </joint>
        <actuator name="base_link_to_wheel2_motor">
            <hardwareInterface>PositionJointInterface</hardwareInterface>
            <mechanicalReduction>1</mechanicalReduction>
        </actuator>
    </transmission>
    <transmission name="trans_base_link_to_wheel3">
        <type>transmission_interface/SimpleTransmission</type>
        <joint name="base_link_to_wheel3">
            <hardwareInterface>PositionJointInterface</hardwareInterface>
        </joint>
        <actuator name="base_link_to_wheel3_motor">
            <hardwareInterface>PositionJointInterface</hardwareInterface>
            <mechanicalReduction>1</mechanicalReduction>
        </actuator>
    </transmission>
    <transmission name="trans_base_link_to_wheel4">
        <type>transmission_interface/SimpleTransmission</type>
        <joint name="base_link_to_wheel4">
            <hardwareInterface>PositionJointInterface</hardwareInterface>
        </joint>
        <actuator name="base_link_to_wheel4_motor">
            <hardwareInterface>PositionJointInterface</hardwareInterface>
            <mechanicalReduction>1</mechanicalReduction>
        </actuator>
    </transmission>
    <transmission name="trans_base_link_to_arm1_link1">
        <type>transmission_interface/SimpleTransmission</type>
        <joint name="base_link_to_arm1_link1">
            <hardwareInterface>PositionJointInterface</hardwareInterface>
        </joint>
        <actuator name="base_link_to_arm1_link1_motor">
            <hardwareInterface>PositionJointInterface</hardwareInterface>
            <mechanicalReduction>1</mechanicalReduction>
        </actuator>
    </transmission>
    <transmission name="trans_arm1_link1_to_link2">
        <type>transmission_interface/SimpleTransmission</type>
        <joint name="arm1_link1_to_link2">
            <hardwareInterface>PositionJointInterface</hardwareInterface>
        </joint>
        <actuator name="arm1_link1_to_link2_motor">
            <hardwareInterface>PositionJointInterface</hardwareInterface>
            <mechanicalReduction>1</mechanicalReduction>
        </actuator>
    </transmission>
    <transmission name="trans_arm1_link2_to_link3">
        <type>transmission_interface/SimpleTransmission</type>
        <joint name="arm1_link2_to_link3">
            <hardwareInterface>PositionJointInterface</hardwareInterface>
        </joint>
        <actuator name="arm1_link2_to_link3_motor">
            <hardwareInterface>PositionJointInterface</hardwareInterface>
            <mechanicalReduction>1</mechanicalReduction>
        </actuator>
    </transmission>
    <transmission name="trans_arm1_link3_to_link4">
        <type>transmission_interface/SimpleTransmission</type>
        <joint name="arm1_link3_to_link4">
            <hardwareInterface>PositionJointInterface</hardwareInterface>
        </joint>
        <actuator name="arm1_link3_to_link4_motor">
            <hardwareInterface>PositionJointInterface</hardwareInterface>
            <mechanicalReduction>1</mechanicalReduction>
        </actuator>
    </transmission>
    <transmission name="trans_arm1_link4_to_left_gripper">
        <type>transmission_interface/SimpleTransmission</type>
        <joint name="arm1_link4_to_left_gripper">
            <hardwareInterface>PositionJointInterface</hardwareInterface>
        </joint>
        <actuator name="arm1_link4_to_left_gripper_motor">
            <hardwareInterface>PositionJointInterface</hardwareInterface>
            <mechanicalReduction>1</mechanicalReduction>
        </actuator>
    </transmission>
    <transmission name="trans_base_link_to_arm2_link1">
        <type>transmission_interface/SimpleTransmission</type>
        <joint name="base_link_to_arm2_link1">
            <hardwareInterface>PositionJointInterface</hardwareInterface>
        </joint>
        <actuator name="base_link_to_arm2_link1_motor">
            <hardwareInterface>PositionJointInterface</hardwareInterface>
            <mechanicalReduction>1</mechanicalReduction>
        </actuator>
    </transmission>
    <transmission name="trans_arm2_link1_to_link2">
        <type>transmission_interface/SimpleTransmission</type>
        <joint name="arm2_link1_to_link2">
            <hardwareInterface>PositionJointInterface</hardwareInterface>
        </joint>
        <actuator name="arm2_link1_to_link2_motor">
            <hardwareInterface>PositionJointInterface</hardwareInterface>
            <mechanicalReduction>1</mechanicalReduction>
        </actuator>
    </transmission>
    <transmission name="trans_arm2_link2_to_link3">
        <type>transmission_interface/SimpleTransmission</type>
        <joint name="arm2_link2_to_link3">
            <hardwareInterface>PositionJointInterface</hardwareInterface>
        </joint>
        <actuator name="arm2_link2_to_link3_motor">
            <hardwareInterface>PositionJointInterface</hardwareInterface>
            <mechanicalReduction>1</mechanicalReduction>
        </actuator>
    </transmission>
    <transmission name="trans_arm2_link3_to_link4">
        <type>transmission_interface/SimpleTransmission</type>
        <joint name="arm2_link3_to_link4">
            <hardwareInterface>PositionJointInterface</hardwareInterface>
        </joint>
        <actuator name="arm2_link3_to_link4_motor">
            <hardwareInterface>PositionJointInterface</hardwareInterface>
            <mechanicalReduction>1</mechanicalReduction>
        </actuator>
    </transmission>
    <gazebo>
        <mu1>50.0</mu1>  
        <mu2>100.0</mu2>  
        <minDepth>0.003</minDepth> 
        <plugin name="gazebo_ros_control" filename="libgazebo_ros_control.so">
            <robotNamespace>/</robotNamespace>
        </plugin>
    </gazebo>

</robot>
