<?xml version="1.0" encoding="utf-8"?>
<!-- This URDF was automatically created by SolidWorks to URDF Exporter! Originally created by Stephen Brawner (brawner@gmail.com) 
     Commit Version: 1.5.1-0-g916b5db  Build Version: 1.5.7152.31018
     For more information, please see http://wiki.ros.org/sw_urdf_exporter -->
<robot
  name="urdf_sim_tutorial">
  <link
    name="base_link">
    <inertial>
      <origin
        xyz="-0.371636722392214 0.0139988026323521 -0.0128778468746189"
        rpy="0 0 0" />
      <mass
        value="1183.08155050657" />
      <inertia
        ixx="372.2306011621"
        ixy="3.78208983204614"
        ixz="48.0097422573757"
        iyy="641.840529280856"
        iyz="-11.8594518724721"
        izz="891.70713474857" />
    </inertial>
    <visual>
      <origin
        xyz="0 0 0"
        rpy="0 0 0" />
      <geometry>
        <mesh
          filename="package://urdf_sim_tutorial/meshes/base_link.STL" />
      </geometry>
      <material
        name="">
        <color
          rgba="0.792156862745098 0.819607843137255 0.933333333333333 1" />
      </material>
    </visual>
    <collision>
      <origin
        xyz="0 0 0"
        rpy="0 0 0" />
      <geometry>
        <mesh
          filename="package://urdf_sim_tutorial/meshes/base_link.STL" />
      </geometry>
    </collision>
  </link>
  <link
    name="wheel1">
    <inertial>
      <origin
        xyz="0 0 -2.2204E-16"
        rpy="0 0 0" />
      <mass
        value="3.2398" />
      <inertia
        ixx="0.015739"
        ixy="2.1176E-20"
        ixz="-4.2352E-20"
        iyy="0.010876"
        iyz="-5.5739E-19"
        izz="0.010876" />
    </inertial>
    <visual>
      <origin
        xyz="0 0 0"
        rpy="0 0 0" />
      <geometry>
        <mesh
          filename="package://urdf_sim_tutorial/meshes/wheel1.STL" />
      </geometry>
      <material
        name="">
        <color
          rgba="0.79216 0.81961 0.93333 1" />
      </material>
    </visual>
    <collision>
      <origin
        xyz="0 0 0"
        rpy="0 0 0" />
      <geometry>
        <mesh
          filename="package://urdf_sim_tutorial/meshes/wheel1.STL" />
      </geometry>
    </collision>
  </link>
  <joint
    name="base_link_to_wheel1"
    type="continuous">
    <origin
      xyz="1.125 -0.725 -0.37"
      rpy="0 0 0" />
    <parent
      link="base_link" />
    <child
      link="wheel1" />
    <axis
      xyz="1 0 0" />
    <limit
      effort="1000"
      velocity="0.5" />
  </joint>
  <link
    name="wheel2">
    <inertial>
      <origin
        xyz="4.3368E-18 4.4409E-16 0"
        rpy="0 0 0" />
      <mass
        value="3.2398" />
      <inertia
        ixx="0.015739"
        ixy="1.1294E-20"
        ixz="-4.2352E-20"
        iyy="0.010876"
        iyz="-2.1791E-19"
        izz="0.010876" />
    </inertial>
    <visual>
      <origin
        xyz="0 0 0"
        rpy="0 0 0" />
      <geometry>
        <mesh
          filename="package://urdf_sim_tutorial/meshes/wheel2.STL" />
      </geometry>
      <material
        name="">
        <color
          rgba="0.79216 0.81961 0.93333 1" />
      </material>
    </visual>
    <collision>
      <origin
        xyz="0 0 0"
        rpy="0 0 0" />
      <geometry>
        <mesh
          filename="package://urdf_sim_tutorial/meshes/wheel2.STL" />
      </geometry>
    </collision>
  </link>
  <joint
    name="base_link_to_wheel2"
    type="continuous">
    <origin
      xyz="-1.125 -0.725 -0.37"
      rpy="0 0 0" />
    <parent
      link="base_link" />
    <child
      link="wheel2" />
    <axis
      xyz="1 0 0" />
    <limit
      effort="1000"
      velocity="0.5" />
  </joint>
  <link
    name="wheel3">
    <inertial>
      <origin
        xyz="4.3368E-18 0 0"
        rpy="0 0 0" />
      <mass
        value="3.2398" />
      <inertia
        ixx="0.015739"
        ixy="1.1294E-20"
        ixz="-4.2352E-20"
        iyy="0.010876"
        iyz="-2.1791E-19"
        izz="0.010876" />
    </inertial>
    <visual>
      <origin
        xyz="0 0 0"
        rpy="0 0 0" />
      <geometry>
        <mesh
          filename="package://urdf_sim_tutorial/meshes/wheel3.STL" />
      </geometry>
      <material
        name="">
        <color
          rgba="0.79216 0.81961 0.93333 1" />
      </material>
    </visual>
    <collision>
      <origin
        xyz="0 0 0"
        rpy="0 0 0" />
      <geometry>
        <mesh
          filename="package://urdf_sim_tutorial/meshes/wheel3.STL" />
      </geometry>
    </collision>
  </link>
  <joint
    name="base_link_to_wheel3"
    type="continuous">
    <origin
      xyz="-1.125 0.725 -0.37"
      rpy="0 0 0" />
    <parent
      link="base_link" />
    <child
      link="wheel3" />
    <axis
      xyz="1 0 0" />
    <limit
      effort="1000"
      velocity="0.5" />
  </joint>
  <link
    name="wheel4">
    <inertial>
      <origin
        xyz="0 0 -2.22044604925031E-16"
        rpy="0 0 0" />
      <mass
        value="3.23976742401446" />
      <inertia
        ixx="0.0157386428837066"
        ixy="2.11758236813573E-20"
        ixz="-4.23516473627149E-20"
        iyy="0.0108759237861092"
        iyz="-5.57387383962731E-19"
        izz="0.0108759237861092" />
    </inertial>
    <visual>
      <origin
        xyz="0 0 0"
        rpy="0 0 0" />
      <geometry>
        <mesh
          filename="package://urdf_sim_tutorial/meshes/wheel4.STL" />
      </geometry>
      <material
        name="">
        <color
          rgba="0.792156862745098 0.819607843137255 0.933333333333333 1" />
      </material>
    </visual>
    <collision>
      <origin
        xyz="0 0 0"
        rpy="0 0 0" />
      <geometry>
        <mesh
          filename="package://urdf_sim_tutorial/meshes/wheel4.STL" />
      </geometry>
    </collision>
  </link>
  <joint
    name="base_link_to_wheel4"
    type="continuous">
    <origin
      xyz="1.125 0.725 -0.37"
      rpy="0 0 0" />
    <parent
      link="base_link" />
    <child
      link="wheel4" />
    <axis
      xyz="1 0 0" />
    <limit
      effort="1000"
      velocity="0.5" />
  </joint>
  <link
    name="arm1_link1">
    <inertial>
      <origin
        xyz="0 0 -0.0899421612400215"
        rpy="0 0 0" />
      <mass
        value="30.3337963399308" />
      <inertia
        ixx="0.643246565913193"
        ixy="-5.82335151237331E-18"
        ixz="-1.37821492542742E-18"
        iyy="0.626370474669819"
        iyz="3.82687635178316E-17"
        izz="0.408564224727811" />
    </inertial>
    <visual>
      <origin
        xyz="0 0 0"
        rpy="0 0 0" />
      <geometry>
        <mesh
          filename="package://urdf_sim_tutorial/meshes/arm1_link1.STL" />
      </geometry>
      <material
        name="">
        <color
          rgba="0.792156862745098 0.819607843137255 0.933333333333333 1" />
      </material>
    </visual>
    <collision>
      <origin
        xyz="0 0 0"
        rpy="0 0 0" />
      <geometry>
        <mesh
          filename="package://urdf_sim_tutorial/meshes/arm1_link1.STL" />
      </geometry>
    </collision>
  </link>
  <joint
    name="base_link_to_arm1_link1"
    type="revolute">
    <origin
      xyz="-0.6 -0.3 0.25"
      rpy="0 0 0" />
    <parent
      link="base_link" />
    <child
      link="arm1_link1" />
    <axis
      xyz="0 0 1" />
    <limit
      lower="-3.1415"
      upper="3.1415"
      effort="1000"
      velocity="0.5" />
  </joint>
  <link
    name="arm1_link2">
    <inertial>
      <origin
        xyz="0.902983819640065 -4.44089209850063E-16 -2.22044604925031E-15"
        rpy="0 0 0" />
      <mass
        value="43.5099555921539" />
      <inertia
        ixx="0.168281643345465"
        ixy="-1.2540666210035E-15"
        ixz="2.36969833607552E-15"
        iyy="14.0055904746337"
        iyz="2.84649869472838E-18"
        izz="13.9984094945799" />
    </inertial>
    <visual>
      <origin
        xyz="0 0 0"
        rpy="0 0 0" />
      <geometry>
        <mesh
          filename="package://urdf_sim_tutorial/meshes/arm1_link2.STL" />
      </geometry>
      <material
        name="">
        <color
          rgba="0.792156862745098 0.819607843137255 0.933333333333333 1" />
      </material>
    </visual>
    <collision>
      <origin
        xyz="0 0 0"
        rpy="0 0 0" />
      <geometry>
        <mesh
          filename="package://urdf_sim_tutorial/meshes/arm1_link2.STL" />
      </geometry>
    </collision>
  </link>
  <joint
    name="arm1_link1_to_link2"
    type="revolute">
    <origin
      xyz="0 0 0.13"
      rpy="1.5708 0 0" />
    <parent
      link="arm1_link1" />
    <child
      link="arm1_link2" />
    <axis
      xyz="0 0 1" />
    <limit
      lower="-3.1415"
      upper="3.1415"
      effort="1000"
      velocity="0.5" />
  </joint>
  <link
    name="arm1_link3">
    <inertial>
      <origin
        xyz="0.711593467921136 0 -2.22044604925031E-15"
        rpy="0 0 0" />
      <mass
        value="23.2628594007332" />
      <inertia
        ixx="0.06325543129244"
        ixy="5.74917714779439E-16"
        ixz="1.4799108310986E-15"
        iyy="4.72953406612324"
        iyz="-2.56495131274686E-18"
        izz="4.75227183314536" />
    </inertial>
    <visual>
      <origin
        xyz="0 0 0"
        rpy="0 0 0" />
      <geometry>
        <mesh
          filename="package://urdf_sim_tutorial/meshes/arm1_link3.STL" />
      </geometry>
      <material
        name="">
        <color
          rgba="0.792156862745098 0.819607843137255 0.933333333333333 1" />
      </material>
    </visual>
    <collision>
      <origin
        xyz="0 0 0"
        rpy="0 0 0" />
      <geometry>
        <mesh
          filename="package://urdf_sim_tutorial/meshes/arm1_link3.STL" />
      </geometry>
    </collision>
  </link>
  <joint
    name="arm1_link2_to_link3"
    type="revolute">
    <origin
      xyz="2 0 0"
      rpy="0 0 0" />
    <parent
      link="arm1_link2" />
    <child
      link="arm1_link3" />
    <axis
      xyz="0 0 1" />
    <limit
      lower="-3.1415"
      upper="3.1415"
      effort="1000"
      velocity="0.5" />
  </joint>
  <link
    name="arm1_link4">
    <inertial>
      <origin
        xyz="0.0458902763105655 0 -1.77635683940025E-15"
        rpy="0 0 0" />
      <mass
        value="0.738705735339555" />
      <inertia
        ixx="0.000783663262373398"
        ixy="-4.7286643816136E-20"
        ixz="4.18530464518703E-18"
        iyy="0.00240409553647368"
        iyz="4.05048142524638E-20"
        izz="0.00245672840447926" />
    </inertial>
    <visual>
      <origin
        xyz="0 0 0"
        rpy="0 0 0" />
      <geometry>
        <mesh
          filename="package://urdf_sim_tutorial/meshes/arm1_link4.STL" />
      </geometry>
      <material
        name="">
        <color
          rgba="0.792156862745098 0.819607843137255 0.933333333333333 1" />
      </material>
    </visual>
    <collision>
      <origin
        xyz="0 0 0"
        rpy="0 0 0" />
      <geometry>
        <mesh
          filename="package://urdf_sim_tutorial/meshes/arm1_link4.STL" />
      </geometry>
    </collision>
  </link>
  <joint
    name="arm1_link3_to_link4"
    type="revolute">
    <origin
      xyz="1.5 0 0"
      rpy="0 0 0" />
    <parent
      link="arm1_link3" />
    <child
      link="arm1_link4" />
    <axis
      xyz="0 0 1" />
    <limit
      lower="-3.1415"
      upper="3.1415"
      effort="1000"
      velocity="0.5" />
  </joint>
  <link
    name="right_gripper">
    <inertial>
      <origin
        xyz="0.0804726270850926 -0.0191552112910767 0"
        rpy="0 0 0" />
      <mass
        value="0.389463613830895" />
      <inertia
        ixx="0.000197175326285283"
        ixy="-2.64592532375718E-05"
        ixz="2.47466115353221E-20"
        iyy="0.00151903582942666"
        iyz="2.83004724667055E-21"
        izz="0.00159224799904073" />
    </inertial>
    <visual>
      <origin
        xyz="0 0 0"
        rpy="0 0 0" />
      <geometry>
        <mesh
          filename="package://urdf_sim_tutorial/meshes/right_gripper.STL" />
      </geometry>
      <material
        name="">
        <color
          rgba="0.792156862745098 0.819607843137255 0.933333333333333 1" />
      </material>
    </visual>
    <collision>
      <origin
        xyz="0 0 0"
        rpy="0 0 0" />
      <geometry>
        <mesh
          filename="package://urdf_sim_tutorial/meshes/right_gripper.STL" />
      </geometry>
    </collision>
  </link>
  <joint
    name="arm1_link4_to_right_gripper"
    type="revolute">
    <origin
      xyz="0.13 0 0.025"
      rpy="-1.5708 0 0" />
    <parent
      link="arm1_link4" />
    <child
      link="right_gripper" />
    <axis
      xyz="0 0 1" />
    <limit
      lower="-3.1415"
      upper="3.1415"
      effort="1000"
      velocity="0.2" />
  </joint>
  <link
    name="left_gripper">
    <inertial>
      <origin
        xyz="0.0804726270851583 0.019155211291157 -4.44089209850063E-16"
        rpy="0 0 0" />
      <mass
        value="0.389463613830896" />
      <inertia
        ixx="0.000197175326285283"
        ixy="2.64592532375495E-05"
        ixz="-4.65287688882966E-20"
        iyy="0.00151903582942667"
        iyz="1.53173373019112E-20"
        izz="0.00159224799904074" />
    </inertial>
    <visual>
      <origin
        xyz="0 0 0"
        rpy="0 0 0" />
      <geometry>
        <mesh
          filename="package://urdf_sim_tutorial/meshes/left_gripper.STL" />
      </geometry>
      <material
        name="">
        <color
          rgba="0.792156862745098 0.819607843137255 0.933333333333333 1" />
      </material>
    </visual>
    <collision>
      <origin
        xyz="0 0 0"
        rpy="0 0 0" />
      <geometry>
        <mesh
          filename="package://urdf_sim_tutorial/meshes/left_gripper.STL" />
      </geometry>
    </collision>
  </link>
  <joint
    name="arm1_link4_to_left_gripper"
    type="revolute">
    <origin
      xyz="0.13 0 -0.025"
      rpy="-1.5708 0 0" />
    <parent
      link="arm1_link4" />
    <child
      link="left_gripper" />
    <axis
      xyz="0 0 1" />
    <limit
      lower="-3.1415"
      upper="3.1415"
      effort="1000"
      velocity="0.2" />
  </joint>
  <link
    name="arm2_link1">
    <inertial>
      <origin
        xyz="1.11022302462516E-16 0 0.447068258452662"
        rpy="0 0 0" />
      <mass
        value="51.8945243112741" />
      <inertia
        ixx="7.36751822699342"
        ixy="6.19180632691988E-18"
        ixz="-9.37759875095668E-17"
        iyy="7.36751822699342"
        iyz="9.31714016734916E-17"
        izz="0.374092038847274" />
    </inertial>
    <visual>
      <origin
        xyz="0 0 0"
        rpy="0 0 0" />
      <geometry>
        <mesh
          filename="package://urdf_sim_tutorial/meshes/arm2_link1.STL" />
      </geometry>
      <material
        name="">
        <color
          rgba="0.792156862745098 0.819607843137255 0.933333333333333 1" />
      </material>
    </visual>
    <collision>
      <origin
        xyz="0 0 0"
        rpy="0 0 0" />
      <geometry>
        <mesh
          filename="package://urdf_sim_tutorial/meshes/arm2_link1.STL" />
      </geometry>
    </collision>
  </link>
  <joint
    name="base_link_to_arm2_link1"
    type="prismatic">
    <origin
      xyz="-0.6 0.3 0.25"
      rpy="0 0 0" />
    <parent
      link="base_link" />
    <child
      link="arm2_link1" />
    <axis
      xyz="0 0 1" />
    <limit
      lower="0"
      upper="1.2"
      effort="1000"
      velocity="0.5" />
  </joint>
  <link
    name="arm2_link2">
    <inertial>
      <origin
        xyz="0.913704450398055 0 0"
        rpy="0 0 0" />
      <mass
        value="42.9994467859457" />
      <inertia
        ixx="0.165326010069522"
        ixy="1.23051059813024E-16"
        ixz="-3.95089951747353E-17"
        iyy="13.5814342748696"
        iyz="-2.5095001935787E-19"
        izz="13.5770493940898" />
    </inertial>
    <visual>
      <origin
        xyz="0 0 0"
        rpy="0 0 0" />
      <geometry>
        <mesh
          filename="package://urdf_sim_tutorial/meshes/arm2_link2.STL" />
      </geometry>
      <material
        name="">
        <color
          rgba="0.792156862745098 0.819607843137255 0.933333333333333 1" />
      </material>
    </visual>
    <collision>
      <origin
        xyz="0 0 0"
        rpy="0 0 0" />
      <geometry>
        <mesh
          filename="package://urdf_sim_tutorial/meshes/arm2_link2.STL" />
      </geometry>
    </collision>
  </link>
  <joint
    name="arm2_link1_to_link2"
    type="revolute">
    <origin
      xyz="0 0 1.115"
      rpy="0 0 0" />
    <parent
      link="arm2_link1" />
    <child
      link="arm2_link2" />
    <axis
      xyz="0 0 1" />
    <limit
      lower="-3.1415"
      upper="3.1415"
      effort="1000"
      velocity="0.5" />
  </joint>
  <link
    name="arm2_link3">
    <inertial>
      <origin
        xyz="0.689492548166673 4.44089209850063E-16 0"
        rpy="0 0 0" />
      <mass
        value="22.5128594007332" />
      <inertia
        ixx="0.0616929312924398"
        ixy="6.50213542918934E-18"
        ixz="3.81624878814869E-18"
        iyy="4.38767522512199"
        iyz="3.91742840690276E-19"
        izz="4.40916299214412" />
    </inertial>
    <visual>
      <origin
        xyz="0 0 0"
        rpy="0 0 0" />
      <geometry>
        <mesh
          filename="package://urdf_sim_tutorial/meshes/arm2_link3.STL" />
      </geometry>
      <material
        name="">
        <color
          rgba="0.792156862745098 0.819607843137255 0.933333333333333 1" />
      </material>
    </visual>
    <collision>
      <origin
        xyz="0 0 0"
        rpy="0 0 0" />
      <geometry>
        <mesh
          filename="package://urdf_sim_tutorial/meshes/arm2_link3.STL" />
      </geometry>
    </collision>
  </link>
  <joint
    name="arm2_link2_to_link3"
    type="revolute">
    <origin
      xyz="2 0 0"
      rpy="0 0 0" />
    <parent
      link="arm2_link2" />
    <child
      link="arm2_link3" />
    <axis
      xyz="0 0 1" />
    <limit
      lower="-3.1415"
      upper="3.1415"
      effort="1000"
      velocity="0.5" />
  </joint>
  <link
    name="arm2_link4">
    <inertial>
      <origin
        xyz="0.106269594348745 0.00540353869569854 4.44089209850063E-16"
        rpy="0 0 0" />
      <mass
        value="2.60246123733574" />
      <inertia
        ixx="0.00509270015154007"
        ixy="-0.00237277132947078"
        ixz="2.14277151573474E-20"
        iyy="0.0277706902273737"
        iyz="-1.12635932791541E-19"
        izz="0.0315335946039622" />
    </inertial>
    <visual>
      <origin
        xyz="0 0 0"
        rpy="0 0 0" />
      <geometry>
        <mesh
          filename="package://urdf_sim_tutorial/meshes/arm2_link4.STL" />
      </geometry>
      <material
        name="">
        <color
          rgba="0.792156862745098 0.819607843137255 0.933333333333333 1" />
      </material>
    </visual>
    <collision>
      <origin
        xyz="0 0 0"
        rpy="0 0 0" />
      <geometry>
        <mesh
          filename="package://urdf_sim_tutorial/meshes/arm2_link4.STL" />
      </geometry>
    </collision>
  </link>
  <joint
    name="arm2_link3_to_link4"
    type="revolute">
    <origin
      xyz="1.5 0 0"
      rpy="0 0 0" />
    <parent
      link="arm2_link3" />
    <child
      link="arm2_link4" />
    <axis
      xyz="0 0 1" />
    <limit
      lower="-3.1415"
      upper="3.1415"
      effort="1000"
      velocity="0.5" />
  </joint>

<transmission name="trans_base_link_to_wheel1">
        <type>transmission_interface/SimpleTransmission</type>
        <joint name="base_link_to_wheel1">
            <hardwareInterface>PositionJointInterface</hardwareInterface>
        </joint>
        <actuator name="base_link_to_wheel1_motor">
            <hardwareInterface>PositionJointInterface</hardwareInterface>
            <mechanicalReduction>1</mechanicalReduction>
        </actuator>
    </transmission>
    <transmission name="trans_base_link_to_wheel2">
        <type>transmission_interface/SimpleTransmission</type>
        <joint name="base_link_to_wheel2">
            <hardwareInterface>PositionJointInterface</hardwareInterface>
        </joint>
        <actuator name="base_link_to_wheel2_motor">
            <hardwareInterface>PositionJointInterface</hardwareInterface>
            <mechanicalReduction>1</mechanicalReduction>
        </actuator>
    </transmission>
    <transmission name="trans_base_link_to_wheel3">
        <type>transmission_interface/SimpleTransmission</type>
        <joint name="base_link_to_wheel3">
            <hardwareInterface>PositionJointInterface</hardwareInterface>
        </joint>
        <actuator name="base_link_to_wheel3_motor">
            <hardwareInterface>PositionJointInterface</hardwareInterface>
            <mechanicalReduction>1</mechanicalReduction>
        </actuator>
    </transmission>
    <transmission name="trans_base_link_to_wheel4">
        <type>transmission_interface/SimpleTransmission</type>
        <joint name="base_link_to_wheel4">
            <hardwareInterface>PositionJointInterface</hardwareInterface>
        </joint>
        <actuator name="base_link_to_wheel4_motor">
            <hardwareInterface>PositionJointInterface</hardwareInterface>
            <mechanicalReduction>1</mechanicalReduction>
        </actuator>
    </transmission>
    <transmission name="trans_base_link_to_arm1_link1">
        <type>transmission_interface/SimpleTransmission</type>
        <joint name="base_link_to_arm1_link1">
            <hardwareInterface>PositionJointInterface</hardwareInterface>
        </joint>
        <actuator name="base_link_to_arm1_link1_motor">
            <hardwareInterface>PositionJointInterface</hardwareInterface>
            <mechanicalReduction>1</mechanicalReduction>
        </actuator>
    </transmission>
    <transmission name="trans_arm1_link1_to_link2">
        <type>transmission_interface/SimpleTransmission</type>
        <joint name="arm1_link1_to_link2">
            <hardwareInterface>PositionJointInterface</hardwareInterface>
        </joint>
        <actuator name="arm1_link1_to_link2_motor">
            <hardwareInterface>PositionJointInterface</hardwareInterface>
            <mechanicalReduction>1</mechanicalReduction>
        </actuator>
    </transmission>
    <transmission name="trans_arm1_link2_to_link3">
        <type>transmission_interface/SimpleTransmission</type>
        <joint name="arm1_link2_to_link3">
            <hardwareInterface>PositionJointInterface</hardwareInterface>
        </joint>
        <actuator name="arm1_link2_to_link3_motor">
            <hardwareInterface>PositionJointInterface</hardwareInterface>
            <mechanicalReduction>1</mechanicalReduction>
        </actuator>
    </transmission>
    <transmission name="trans_arm1_link3_to_link4">
        <type>transmission_interface/SimpleTransmission</type>
        <joint name="arm1_link3_to_link4">
            <hardwareInterface>PositionJointInterface</hardwareInterface>
        </joint>
        <actuator name="arm1_link3_to_link4_motor">
            <hardwareInterface>PositionJointInterface</hardwareInterface>
            <mechanicalReduction>1</mechanicalReduction>
        </actuator>
    </transmission>
    <transmission name="trans_arm1_link4_to_right_gripper">
        <type>transmission_interface/SimpleTransmission</type>
        <joint name="arm1_link4_to_right_gripper">
            <hardwareInterface>PositionJointInterface</hardwareInterface>
        </joint>
        <actuator name="arm1_link4_to_right_gripper_motor">
            <hardwareInterface>PositionJointInterface</hardwareInterface>
            <mechanicalReduction>1</mechanicalReduction>
        </actuator>
    </transmission>
    <transmission name="trans_arm1_link4_to_left_gripper">
        <type>transmission_interface/SimpleTransmission</type>
        <joint name="arm1_link4_to_left_gripper">
            <hardwareInterface>PositionJointInterface</hardwareInterface>
        </joint>
        <actuator name="arm1_link4_to_left_gripper_motor">
            <hardwareInterface>PositionJointInterface</hardwareInterface>
            <mechanicalReduction>1</mechanicalReduction>
        </actuator>
    </transmission>
    <transmission name="trans_base_link_to_arm2_link1">
        <type>transmission_interface/SimpleTransmission</type>
        <joint name="base_link_to_arm2_link1">
            <hardwareInterface>PositionJointInterface</hardwareInterface>
        </joint>
        <actuator name="base_link_to_arm2_link1_motor">
            <hardwareInterface>PositionJointInterface</hardwareInterface>
            <mechanicalReduction>1</mechanicalReduction>
        </actuator>
    </transmission>
    <transmission name="trans_arm2_link1_to_link2">
        <type>transmission_interface/SimpleTransmission</type>
        <joint name="arm2_link1_to_link2">
            <hardwareInterface>PositionJointInterface</hardwareInterface>
        </joint>
        <actuator name="arm2_link1_to_link2_motor">
            <hardwareInterface>PositionJointInterface</hardwareInterface>
            <mechanicalReduction>1</mechanicalReduction>
        </actuator>
    </transmission>
    <transmission name="trans_arm2_link2_to_link3">
        <type>transmission_interface/SimpleTransmission</type>
        <joint name="arm2_link2_to_link3">
            <hardwareInterface>PositionJointInterface</hardwareInterface>
        </joint>
        <actuator name="arm2_link2_to_link3_motor">
            <hardwareInterface>PositionJointInterface</hardwareInterface>
            <mechanicalReduction>1</mechanicalReduction>
        </actuator>
    </transmission>
    <transmission name="trans_arm2_link3_to_link4">
        <type>transmission_interface/SimpleTransmission</type>
        <joint name="arm2_link3_to_link4">
            <hardwareInterface>PositionJointInterface</hardwareInterface>
        </joint>
        <actuator name="arm2_link3_to_link4_motor">
            <hardwareInterface>PositionJointInterface</hardwareInterface>
            <mechanicalReduction>1</mechanicalReduction>
        </actuator>
    </transmission>
    <gazebo>
        <plugin name="gazebo_ros_control" filename="libgazebo_ros_control.so">
            <robotNamespace>/</robotNamespace>
        </plugin>
    </gazebo>


</robot>
